[2023-03-12T13:15:00.867+0000] {taskinstance.py:1083} INFO - Dependencies all met for <TaskInstance: Dag_master.dag_2_completed_status scheduled__2023-03-12T13:14:00+00:00 [queued]>
[2023-03-12T13:15:00.877+0000] {taskinstance.py:1083} INFO - Dependencies all met for <TaskInstance: Dag_master.dag_2_completed_status scheduled__2023-03-12T13:14:00+00:00 [queued]>
[2023-03-12T13:15:00.877+0000] {taskinstance.py:1279} INFO - 
--------------------------------------------------------------------------------
[2023-03-12T13:15:00.877+0000] {taskinstance.py:1280} INFO - Starting attempt 1 of 1
[2023-03-12T13:15:00.877+0000] {taskinstance.py:1281} INFO - 
--------------------------------------------------------------------------------
[2023-03-12T13:15:00.894+0000] {taskinstance.py:1300} INFO - Executing <Task(ExternalTaskSensor): dag_2_completed_status> on 2023-03-12 13:14:00+00:00
[2023-03-12T13:15:00.904+0000] {standard_task_runner.py:55} INFO - Started process 833 to run task
[2023-03-12T13:15:00.906+0000] {standard_task_runner.py:82} INFO - Running: ['***', 'tasks', 'run', 'Dag_master', 'dag_2_completed_status', 'scheduled__2023-03-12T13:14:00+00:00', '--job-id', '25', '--raw', '--subdir', 'DAGS_FOLDER/child_master_dag.py', '--cfg-path', '/tmp/tmpq7nwo0j8']
[2023-03-12T13:15:00.907+0000] {standard_task_runner.py:83} INFO - Job 25: Subtask dag_2_completed_status
[2023-03-12T13:15:00.966+0000] {task_command.py:388} INFO - Running <TaskInstance: Dag_master.dag_2_completed_status scheduled__2023-03-12T13:14:00+00:00 [running]> on host 85f2bfd08863
[2023-03-12T13:15:01.033+0000] {taskinstance.py:1509} INFO - Exporting the following env vars:
AIRFLOW_CTX_DAG_OWNER=***
AIRFLOW_CTX_DAG_ID=Dag_master
AIRFLOW_CTX_TASK_ID=dag_2_completed_status
AIRFLOW_CTX_EXECUTION_DATE=2023-03-12T13:14:00+00:00
AIRFLOW_CTX_TRY_NUMBER=1
AIRFLOW_CTX_DAG_RUN_ID=scheduled__2023-03-12T13:14:00+00:00
[2023-03-12T13:15:01.057+0000] {taskinstance.py:1768} ERROR - Task failed with exception
Traceback (most recent call last):
  File "/home/airflow/.local/lib/python3.7/site-packages/airflow/sensors/base.py", line 199, in execute
    poke_return = self.poke(context)
  File "/home/airflow/.local/lib/python3.7/site-packages/airflow/utils/session.py", line 75, in wrapper
    return func(*args, session=session, **kwargs)
  File "/home/airflow/.local/lib/python3.7/site-packages/airflow/sensors/external_task.py", line 222, in poke
    self._check_for_existence(session=session)
  File "/home/airflow/.local/lib/python3.7/site-packages/airflow/sensors/external_task.py", line 266, in _check_for_existence
    raise AirflowException(f"The external DAG {self.external_dag_id} does not exist.")
airflow.exceptions.AirflowException: The external DAG dag_2 does not exist.
[2023-03-12T13:15:01.060+0000] {taskinstance.py:1323} INFO - Marking task as FAILED. dag_id=Dag_master, task_id=dag_2_completed_status, execution_date=20230312T131400, start_date=20230312T131500, end_date=20230312T131501
[2023-03-12T13:15:01.071+0000] {standard_task_runner.py:105} ERROR - Failed to execute job 25 for task dag_2_completed_status (The external DAG dag_2 does not exist.; 833)
[2023-03-12T13:15:01.119+0000] {local_task_job.py:208} INFO - Task exited with return code 1
[2023-03-12T13:15:01.158+0000] {taskinstance.py:2578} INFO - 0 downstream tasks scheduled from follow-on schedule check
