[2023-03-12T13:10:04.974+0000] {taskinstance.py:1083} INFO - Dependencies all met for <TaskInstance: Dag_master.dag_2_completed_status scheduled__2023-03-12T13:09:00+00:00 [queued]>
[2023-03-12T13:10:04.988+0000] {taskinstance.py:1083} INFO - Dependencies all met for <TaskInstance: Dag_master.dag_2_completed_status scheduled__2023-03-12T13:09:00+00:00 [queued]>
[2023-03-12T13:10:04.989+0000] {taskinstance.py:1279} INFO - 
--------------------------------------------------------------------------------
[2023-03-12T13:10:04.989+0000] {taskinstance.py:1280} INFO - Starting attempt 1 of 1
[2023-03-12T13:10:04.989+0000] {taskinstance.py:1281} INFO - 
--------------------------------------------------------------------------------
[2023-03-12T13:10:05.009+0000] {taskinstance.py:1300} INFO - Executing <Task(ExternalTaskSensor): dag_2_completed_status> on 2023-03-12 13:09:00+00:00
[2023-03-12T13:10:05.058+0000] {standard_task_runner.py:55} INFO - Started process 236 to run task
[2023-03-12T13:10:05.061+0000] {standard_task_runner.py:82} INFO - Running: ['***', 'tasks', 'run', 'Dag_master', 'dag_2_completed_status', 'scheduled__2023-03-12T13:09:00+00:00', '--job-id', '16', '--raw', '--subdir', 'DAGS_FOLDER/child_master_dag.py', '--cfg-path', '/tmp/tmp_zmjcs43']
[2023-03-12T13:10:05.062+0000] {standard_task_runner.py:83} INFO - Job 16: Subtask dag_2_completed_status
[2023-03-12T13:10:05.121+0000] {task_command.py:388} INFO - Running <TaskInstance: Dag_master.dag_2_completed_status scheduled__2023-03-12T13:09:00+00:00 [running]> on host 85f2bfd08863
[2023-03-12T13:10:05.201+0000] {taskinstance.py:1509} INFO - Exporting the following env vars:
AIRFLOW_CTX_DAG_OWNER=***
AIRFLOW_CTX_DAG_ID=Dag_master
AIRFLOW_CTX_TASK_ID=dag_2_completed_status
AIRFLOW_CTX_EXECUTION_DATE=2023-03-12T13:09:00+00:00
AIRFLOW_CTX_TRY_NUMBER=1
AIRFLOW_CTX_DAG_RUN_ID=scheduled__2023-03-12T13:09:00+00:00
[2023-03-12T13:10:05.221+0000] {taskinstance.py:1768} ERROR - Task failed with exception
Traceback (most recent call last):
  File "/home/airflow/.local/lib/python3.7/site-packages/airflow/sensors/base.py", line 199, in execute
    poke_return = self.poke(context)
  File "/home/airflow/.local/lib/python3.7/site-packages/airflow/utils/session.py", line 75, in wrapper
    return func(*args, session=session, **kwargs)
  File "/home/airflow/.local/lib/python3.7/site-packages/airflow/sensors/external_task.py", line 222, in poke
    self._check_for_existence(session=session)
  File "/home/airflow/.local/lib/python3.7/site-packages/airflow/sensors/external_task.py", line 266, in _check_for_existence
    raise AirflowException(f"The external DAG {self.external_dag_id} does not exist.")
airflow.exceptions.AirflowException: The external DAG dag_2 does not exist.
[2023-03-12T13:10:05.225+0000] {taskinstance.py:1323} INFO - Marking task as FAILED. dag_id=Dag_master, task_id=dag_2_completed_status, execution_date=20230312T130900, start_date=20230312T131004, end_date=20230312T131005
[2023-03-12T13:10:05.236+0000] {standard_task_runner.py:105} ERROR - Failed to execute job 16 for task dag_2_completed_status (The external DAG dag_2 does not exist.; 236)
[2023-03-12T13:10:05.273+0000] {local_task_job.py:208} INFO - Task exited with return code 1
[2023-03-12T13:10:05.306+0000] {taskinstance.py:2578} INFO - 0 downstream tasks scheduled from follow-on schedule check
